Workbook

Sheet Readme
A1: HuntOS — СОЛО-БУТСТРАП (0 инвесторов, 0 команды, старт с 0 юзеров)
A3: Две кассы + честный runway ~13м. Главный баг старой версии — СКОРОСТЬ набора (10/мес = смерть).
A4: Base: цель ~100 signups/мес1 (партизанский GTM). Pes = старый тихий набор (~12/мес).
A5: Plus 990 = касса; Lifetime 2990/3м = быстрый cash; Pro 1990 позже. Free AI-taste.
A6: Activation в модели 15% (не 40%). CAC Y1≈400 → Y2≈1800; referral −25% с м.6.
A7: B2B с WAS≳500 (агрегаты рынка). Offer-radar конкурентам — НЕ в модели (legal: спросить).
A8: Лист Plan = GTM + продукт (Career OS). Product / Bootstrap / Unit — цифры.

Sheet Plan
A1: PLAN — выход из долины смерти (CPO/board 2026)
A2: Ввод аудита, не закон. Owner-канон: .cursor/rules/huntos-strategy.mdc
A4: УГРОЗА | B4: Скорость: 7–15 signup/мес → нет A/B, нет статистики, runway сгорает на м.13–14.
A5: ПРАВИЛО 1 | B5: Цель 30 дней: 100 signups (TG/LinkedIn/Habr/друзья), не 15.
A6: ПРАВИЛО 2 | B6: Первые 3 мес продавать Plus 990 (+ Lifetime 2990). Не упираться в 1990.
A7: ПРАВИЛО 3 | B7: B2B-шлюпка при WAS≳500: агрегаты рынка HR/изданиям — не персональный offer-radar.
A8: GTM 1 | B8: Консьерж-MVP: кнопка AI → TG; «скинь 990 на карту» до ЮKassa. Willingness-to-pay до биллинга.
A9: GTM 2 | B9: Habr/VC: жёсткая статья про боль HH/ATS → ссылка на CRM. 1 пост = потенциально 1–3k regs.
A10: GTM 3 | B10: Chrome clipper = бесплатный троян: инжест вакансий + база для SEO-агрегатора.
A11: GTM 4 | B11: Freemium trap: пуш на стадии «Отправлено» → follow-up AI (страх неопределённости).
A12: GTM 5 | B12: Build-in-public TG-канал фаундера → CAC≈0 на первых сотнях.
A13: PROD 1 | B13: Zero-Data onboarding: PDF резюме → 3 карточки сразу (activation 15%→выше).
A14: PROD 2 | B14: Продавать ATS-bypass / буллеты / keywords, не простыни cover letter.
A15: PROD 3 | B15: TG-бот MUST: ссылка→карточка + «завтра собес → шпаргалка».
... A23: ФАЗА 3 | B23: B2B агрегаты (скорость найма). Shareable CV link для прогрева работодателей.

Sheet Product
A1: PRODUCT — кто юзер, полярная звезда, конверсия
A3: 1. Кто такой юзер
A4: User (счётчик базы) | B4: Любой зарегистрированный аккаунт (есть login).
A5: ICP (платящий) | B5: IT Middle/Senior или релокант; активный поиск; ЗП ≳150k; болит ATS/воронка.
A6: Не ICP | B6: «Просто смотрю рынок», junior без бюджета, карьерный турист, HR/коуч.
A7: Free-ценность | B7: CRM + клиппер + resume PDF + AI-taste (3 мэтча). Не жечь токены.
A8: Paid-ценность | B8: Plus 990: ATS-bypass/адаптация/follow-up. Lifetime 2990/3м. Pro позже.
A9: Почему минус | B9: EBITDA < 0 из‑за VPS/админ/CAC, не GLM. Домен 1×/год.
A10: Позиционирование | B10: Career OS (резюме-якорь + воронка), не «ещё один канбан».
A12: 2. North Star
A13: WAS | B13: Weekly Active Searchers = сдвиг ≥1 карточки вакансии за 7 дней.
A14: Time-to-100 | B14: Месяц, когда база ≥100 юзеров (нужна статистика, не 10 regs).
A15: Guardrail $ | B15: Paying + MRR + Lifetime cash. WAS↑ без pay → слабый пейволл.
A16: Цель | B16: 60 платящих + Personal не в ноль до дивиденда с продукта.
A18: 3. Воронка (жёсткие цифры)
A19: Шаг | B19: Base | C19: Opt | D19: Pes
A20: Signup → Activated (7д) | B20: 15% | C20: 25% | D20: 10%
A21: Activated → Paid (≈ stock/act) | B21: 27% | C21: 28% | D21: 20%
A22: Stock платящих от базы | B22: 4% | C22: 7% | D22: 2%
A23: Микс among paid (early) | B23: Lite20/Plus70/Pro10 | C23: больше Plus | D23: больше Lite
A24: Lifetime share of new pay | B24: 30% | C24: 40% | D24: 15%
A25: Industry activation (справка) | B25: B2C часто 15–20%, не 40%
A27: 4. LLM vs серверы
A28: LLM Free ₽/юзер/мес | B28: 0.00335475
A29: LLM на платящего | B29: 0.25679682
A30: ARPU платящего (sub) | B30: 990
A31: Lifetime цена | B31: 2990
A32: Запас sub после LLM | B32: 989.7432
A33: Вывод | B33: Модель окупается. Угроза = медленный набор и Personal runway, не GLM.
A35: Срез base мес12 | B35: users=1900 WAS≈475 pay=76 rev=78157
A36: Time-to-100 / 60 pay / runway | B36: 1 / 11 / None

Sheet Inputs
A1: INPUTS — соло-бутстрап
A4: A. Макро
A5: Курс USD/RUB | B5: 90
A6: Эквайринг | B6: 0.03
A7: УСН | B7: 0.06
A9: B. Цены
A10: Free | B10: 0
A11: Lite | B11: 490 | D11: early — не касса
A12: Plus | B12: 990 | D12: касса первых месяцев
A13: Pro | B13: 1990 | D13: после доверия / decoy
A14: Lifetime «до оффера» | B14: 2990 | D14: покрывает ~3 мес
A15: Доля новых pay → Lifetime | B15: 0.3
A17: C. Микс BASE (~4% paid, Plus-heavy)
A18: Free % | B18: 0.96
A19: Lite % | B19: 0.008 | D19: ~20% among paid
A20: Plus % | B20: 0.028 | D20: ~70% among paid — касса
A21: Pro % | B21: 0.004 | D21: ~10% among paid
A23: D. Набор с НУЛЯ (цель 100/мес1)
A24: Юзеры на старте | B24: 0 | D24: должно быть 0
A25: Регистраций в мес 1 | B25: 100 | D25: CPO: иначе нет A/B
A26: Рост набора MoM | B26: 0.12
A27: Churn базы | B27: 0.06
A28: Месяцев soft-launch | B28: 0 | D28: 0 = не душить старт
A29: Коэф soft-launch | B29: 1
A30: Churn платящих | B30: 0.25 | D30: нашёл работу → отписка
A31: Activation signup→act | B31: 0.15 | D31: не 40% — розовые очки
A33: E. LLM (min burn)
A34: Input $/1M | B34: 0.15
A35: Output $/1M | B35: 0.5
A36: Cache $/1M | B36: 0.03
A37: Cache hit | B37: 0.7
A38: Util лимита (paid) | B38: 0.35
A39: Токены мэтч in | B39: 450
A40: Токены мэтч out | B40: 40
A41: Токены письмо in | B41: 1800
A42: Токены письмо out | B42: 280
A43: Токены адапт in | B43: 2200
A44: Токены адапт out | B44: 500
A45: Токены TG in | B45: 500
... A63: Порог выручки для ИП | B63: 10000
...

Sheet Bootstrap
A1: BOOTSTRAP — путь с нуля без инвесторов
A2: Смотри сюда, если запускаешь один. PnL — детализация тех же цифр.
A4: Реальность старта
A5: Инвесторы | B5: нет
A6: Команда | B6: 1 человек (ты)
A7: Юзеры день 0 | B7: 0
A8: Личные накопления | B8: =Inputs!$B$89 -> 300000
A9: Жизнь ₽/мес | B9: =Inputs!$B$90 -> 60000
A10: Подработка ₽/мес | B10: =Inputs!$B$91 -> 40000
A11: Чистый личный burn ₽/мес | B11: =Inputs!$B$90-Inputs!$B$91 -> 20000
A12: Runway месяцев (грубо) | B12: =IF((Inputs!$B$90-Inputs!$B$91)<=0,99,INT(Inputs!$B$89/MAX(1,Inputs!$B$90-Inputs!$B$91))) -> 15
A13: Месяц первого платящего (base) | B13: 1
A14: Time-to-100 users (base) | B14: 1
A15: Месяц 60 платящих (base) | B15: 11
A16: Личные деньги кончаются (base) | B16: хватает на 24м
A17: Месяц 60 платящих (opt) | B17: 4
A18: Личные деньги кончаются (pes) | B18: 14
A19: Pes = долина смерти (тихий набор) | B19: acq×0.12
A21: Что делать руками первые 90 дней
A22: 1. Консьерж: AI-кнопка → TG → 990 на карту. Не жди ЮKassa.
A23: 2. Цель 100 regs/мес: TG-чаты + LinkedIn + Habr/VC + build-in-public.
A24: 3. Clipper + TG-бот (ссылка→карточка). PDF onboarding → 3 карточки.
A25: 4. Касса = Plus 990 + Lifetime 2990. Free = CRM+PDF+taste. Минус = VPS.
A26: 5. B2B агрегаты после WAS≳500. Intent/offer-radar — НЕ без спроса владельцу.
A27: 6. Personal burn = жизнь − подработка. Следи за м.13.
A30: Помесячно BASE
A31: Мес | B31: Signups | C31: Юзеры | D31: WAS | E31: Платящие | F31: Rev sub | G31: Rev LT | H31: Выручка | I31: EBITDA | J31: Personal
A32: 1 | B32: =PnL!B4 -> 100 | C32: =PnL!B5 -> 100 | D32: =PnL!B6 -> 25 | E32: =PnL!B7 -> 4 | F32: =PnL!B8 -> 2772 | G32: =PnL!B9 -> 3588 | H32: =PnL!B12 -> 6360 | I32: =PnL!B23 -> -2344.9652 | J32: =CashFlow!B13 -> 280000
A33: 2 | B33: =PnL!C4 -> 112 | C33: =PnL!C5 -> 206 | D33: =PnL!C6 -> 51.5 | E33: =PnL!C7 -> 8.24 | F33: =PnL!C8 -> 5413.32 | G33: =PnL!C9 -> 4700.28 | H33: =PnL!C12 -> 10113.6 | I33: =PnL!C23 -> -3430.8594 | J33: =CashFlow!C13 -> 260000
A34: 3 | B34: =PnL!D4 -> 125.44 | C34: =PnL!D5 -> 319.08 | D34: =PnL!D6 -> 79.77 | E34: =PnL!D7 -> 12.7632 | F34: =PnL!D8 -> 7936.0776 | G34: =PnL!D9 -> 5905.1304 | H34: =PnL!D12 -> 13841.208 | I34: =PnL!D23 -> -582.06509 | J34: =CashFlow!D13 -> 240000
A35: 4 | B35: =PnL!E4 -> 140.4928 | C35: =PnL!E5 -> 440.428 | D35: =PnL!E6 -> 110.107 | E35: =PnL!E7 -> 17.61712 | F35: =PnL!E8 -> 11540.177 | G35: =PnL!E9 -> 7216.1138 | H35: =PnL!E12 -> 18756.29 | I35: =PnL!E23 -> 3299.5607 | J35: =CashFlow!E13 -> 220000
A36: 5 | B36: =PnL!F4 -> 157.35194 | C36: =PnL!F5 -> 571.35426 | D36: =PnL!F6 -> 142.83856 | E36: =PnL!F7 -> 22.85417 | F36: =PnL!F8 -> 15417.661 | G36: =PnL!F9 -> 8648.2732 | H36: =PnL!F12 -> 24065.934 | I36: =PnL!F23 -> -3514.3109 | J36: =CashFlow!F13 -> 200000
A37: 6 | B37: =PnL!G4 -> 176.23417 | C37: =PnL!G5 -> 713.30717 | D37: =PnL!G6 -> 178.32679 | E37: =PnL!G7 -> 28.532287 | F37: =PnL!G8 -> 19610.884 | G37: =PnL!G9 -> 10218.318 | H37: =PnL!G12 -> 29829.202 | I37: =PnL!G23 -> 2161.7039 | J37: =CashFlow!G13 -> 180000
A38: 7 | B38: =PnL!H4 -> 197.38227 | C38: =PnL!H5 -> 867.89101 | D38: =PnL!H6 -> 216.97275 | E38: =PnL!H7 -> 34.71564 | F38: =PnL!H8 -> 24166.708 | G38: =PnL!H9 -> 11944.833 | H38: =PnL!H12 -> 36111.541 | I38: =PnL!H23 -> 7292.9333 | J38: =CashFlow!H13 -> 160000
A39: 8 | B39: =PnL!I4 -> 221.06814 | C39: =PnL!I5 -> 1036.8857 | D39: =PnL!I6 -> 259.22142 | E39: =PnL!I7 -> 41.475428 | F39: =PnL!I8 -> 29137.079 | G39: =PnL!I9 -> 13848.511 | H39: =PnL!I12 -> 42985.591 | I39: =PnL!I23 -> 12902.597 | J39: =CashFlow!I13 -> 140000
A40: 9 | B40: =PnL!J4 -> 247.59632 | C40: =PnL!J5 -> 1222.2689 | D40: =PnL!J6 -> 305.56722 | E40: =PnL!J7 -> 48.890755 | F40: =PnL!J8 -> 34579.673 | G40: =PnL!J9 -> 15952.413 | H40: =PnL!J12 -> 50532.086 | I40: =PnL!J23 -> 19056.345 | J40: =CashFlow!J13 -> 120000
A41: 10 | B41: =PnL!K4 -> 277.30788 | C41: =PnL!K5 -> 1426.2406 | D41: =PnL!K6 -> 356.56015 | E41: =PnL!K7 -> 57.049624 | F41: =PnL!K8 -> 40558.61 | G41: =PnL!K9 -> 18282.258 | H41: =PnL!K12 -> 58840.867 | I41: =PnL!K23 -> 25827.213 | J41: =CashFlow!K13 -> 100000
A42: 11 | B42: =PnL!L4 -> 310.58482 | C42: =PnL!L5 -> 1651.251 | D42: =PnL!L6 -> 412.81275 | E42: =PnL!L7 -> 66.05004 | F42: =PnL!L8 -> 47145.256 | G42: =PnL!L9 -> 20866.751 | H42: =PnL!L12 -> 68012.007 | I42: =PnL!L23 -> 33296.534 | J42: =CashFlow!L13 -> 80000
A43: 12 | B43: =PnL!M4 -> 347.855 | C43: =PnL!M5 -> 1900.0309 | D43: =PnL!M6 -> 475.00773 | E43: =PnL!M7 -> 76.001237 | F43: =PnL!M8 -> 54419.123 | G43: =PnL!M9 -> 23737.946 | H43: =PnL!M12 -> 78157.069 | I43: =PnL!M23 -> 41554.967 | J43: =CashFlow!M13 -> 60000
A44: 13 | B44: =PnL!N4 -> 389.5976 | C44: =PnL!N5 -> 2175.6267 | D44: =PnL!N6 -> 543.90667 | E44: =PnL!N7 -> 87.025067 | F44: =PnL!N8 -> 62468.868 | G44: =PnL!N9 -> 26931.653 | H44: =PnL!N12 -> 164400.52 | I44: =PnL!N23 -> 58214.145 | J44: =CashFlow!N13 -> 48214.145
...

Sheet PnL
A1: PnL 24м — Base соло
A3: Месяц | B3: 1 | C3: 2 | D3: 3 | E3: 4 | F3: 5 | G3: 6 | H3: 7 | I3: 8 | J3: 9 | K3: 10 | L3: 11 | M3: 12 | N3: 13 | O3: 14 | P3: 15 | Q3: 16 | R3: 17 | S3: 18 | T3: 19 | U3: 20 | V3: 21 | W3: 22 | X3: 23 | Y3: 24
A4: Signups | B4: =Inputs!$B$25*(1+Inputs!$B$26)^(B3-1)*IF(B3<=Inputs!$B$28,Inputs!$B$29,1) -> 100 | C4: =Inputs!$B$25*(1+Inputs!$B$26)^(C3-1)*IF(C3<=Inputs!$B$28,Inputs!$B$29,1) -> 112 | D4: =Inputs!$B$25*(1+Inputs!$B$26)^(D3-1)*IF(D3<=Inputs!$B$28,Inputs!$B$29,1) -> 125.44 | E4: =Inputs!$B$25*(1+Inputs!$B$26)^(E3-1)*IF(E3<=Inputs!$B$28,Inputs!$B$29,1) -> 140.4928 | F4: =Inputs!$B$25*(1+Inputs!$B$26)^(F3-1)*IF(F3<=Inputs!$B$28,Inputs!$B$29,1) -> 157.35194 | G4: =Inputs!$B$25*(1+Inputs!$B$26)^(G3-1)*IF(G3<=Inputs!$B$28,Inputs!$B$29,1) -> 176.23417 | H4: =Inputs!$B$25*(1+Inputs!$B$26)^(H3-1)*IF(H3<=Inputs!$B$28,Inputs!$B$29,1) -> 197.38227 | I4: =Inputs!$B$25*(1+Inputs!$B$26)^(I3-1)*IF(I3<=Inputs!$B$28,Inputs!$B$29,1) -> 221.06814 | ... Y4: =Inputs!$B$25*(1+Inputs!$B$26)^(Y3-1)*IF(Y3<=Inputs!$B$28,Inputs!$B$29,1) -> 1355.2347
A5: Юзеры | B5: =Inputs!$B$24*(1-Inputs!$B$27)+B4 -> 100 | C5: =B5*(1-Inputs!$B$27)+C4 -> 206 | D5: =C5*(1-Inputs!$B$27)+D4 -> 319.08 | E5: =D5*(1-Inputs!$B$27)+E4 -> 440.428 | F5: =E5*(1-Inputs!$B$27)+F4 -> 571.35426 | G5: =F5*(1-Inputs!$B$27)+G4 -> 713.30717 | H5: =G5*(1-Inputs!$B$27)+H4 -> 867.89101 | I5: =H5*(1-Inputs!$B$27)+I4 -> 1036.8857 | J5: =I5*(1-Inputs!$B$27)+J4 -> 1222.2689 | ... Y5: =X5*(1-Inputs!$B$27)+Y4 -> 8306.7382
A6: WAS | B6: =B5*Inputs!$B$60 -> 25 | C6: =C5*Inputs!$B$60 -> 51.5 | D6: =D5*Inputs!$B$60 -> 79.77 | E6: =E5*Inputs!$B$60 -> 110.107 | F6: =F5*Inputs!$B$60 -> 142.83856 | G6: =G5*Inputs!$B$60 -> 178.32679 | H6: =H5*Inputs!$B$60 -> 216.97275 | I6: =I5*Inputs!$B$60 -> 259.22142 | ... Y6: =Y5*Inputs!$B$60 -> 2076.6846
A7: Платящие | B7: =B5*Inputs!$B$112 -> 4 | C7: =C5*Inputs!$B$112 -> 8.24 | D7: =D5*Inputs!$B$112 -> 12.7632 | E7: =E5*Inputs!$B$112 -> 17.61712 | F7: =F5*Inputs!$B$112 -> 22.85417 | G7: =G5*Inputs!$B$112 -> 28.532287 | H7: =H5*Inputs!$B$112 -> 34.71564 | I7: =I5*Inputs!$B$112 -> 41.475428 | ... Y7: =Y5*Inputs!$B$112 -> 332.26953
A8: Выручка sub | B8: =B39*Inputs!$B$114 -> 2772 | C8: =C39*Inputs!$B$114 -> 5413.32 | D8: =D39*Inputs!$B$114 -> 7936.0776 | E8: =E39*Inputs!$B$114 -> 11540.177 | F8: =F39*Inputs!$B$114 -> 15417.661 | G8: =G39*Inputs!$B$114 -> 19610.884 | H8: =H39*Inputs!$B$114 -> 24166.708 | I8: =I39*Inputs!$B$114 -> 29137.079 | ... Y8: =Y39*Inputs!$B$114 -> 240885.62
A9: Выручка Lifetime | B9: =B37*Inputs!$B$14 -> 3588 | C9: =C37*Inputs!$B$14 -> 4700.28 | D9: =D37*Inputs!$B$14 -> 5905.1304 | E9: =E37*Inputs!$B$14 -> 7216.1138 | F9: =F37*Inputs!$B$14 -> 8648.2732 | G9: =G37*Inputs!$B$14 -> 10218.318 | H9: =H37*Inputs!$B$14 -> 11944.833 | I9: =I37*Inputs!$B$14 -> 13848.511 | ... Y9: =Y37*Inputs!$B$14 -> 99040.492
A10: Выручка B2C | B10: =B8+B9 -> 6360 | C10: =C8+C9 -> 10113.6 | D10: =D8+D9 -> 13841.208 | E10: =E8+E9 -> 18756.29 | F10: =F8+F9 -> 24065.934 | G10: =G8+G9 -> 29829.202 | H10: =H8+H9 -> 36111.541 | I10: =I8+I9 -> 42985.591 | ... Y10: =Y8+Y9 -> 339926.11
A11: Выручка B2B | B11: =IF(OR(B3<Inputs!$B$84,B6<Inputs!$B$85),0,MIN(Inputs!$B$86,1+INT((B3-Inputs!$B$84)/3)))*Inputs!$B$83 -> 0 | C11: =IF(OR(C3<Inputs!$B$84,C6<Inputs!$B$85),0,MIN(Inputs!$B$86,1+INT((C3-Inputs!$B$84)/3)))*Inputs!$B$83 -> 0 | D11: =IF(OR(D3<Inputs!$B$84,D6<Inputs!$B$85),0,MIN(Inputs!$B$86,1+INT((D3-Inputs!$B$84)/3)))*Inputs!$B$83 -> 0 | E11: =IF(OR(E3<Inputs!$B$84,E6<Inputs!$B$85),0,MIN(Inputs!$B$86,1+INT((E3-Inputs!$B$84)/3)))*Inputs!$B$83 -> 0 | F11: =IF(OR(F3<Inputs!$B$84,F6<Inputs!$B$85),0,MIN(Inputs!$B$86,1+INT((F3-Inputs!$B$84)/3)))*Inputs!$B$83 -> 0 | G11: =IF(OR(G3<Inputs!$B$84,G6<Inputs!$B$85),0,MIN(Inputs!$B$86,1+INT((G3-Inputs!$B$84)/3)))*Inputs!$B$83 -> 0 | H11: =IF(OR(H3<Inputs!$B$84,H6<Inputs!$B$85),0,MIN(Inputs!$B$86,1+INT((H3-Inputs!$B$84)/3)))*Inputs!$B$83 -> 0 | I11: =IF(OR(I3<Inputs!$B$84,I6<Inputs!$B$85),0,MIN(Inputs!$B$86,1+INT((I3-Inputs!$B$84)/3)))*Inputs!$B$83 -> 0 | ... Y11: =IF(OR(Y3<Inputs!$B$84,Y6<Inputs!$B$85),0,MIN(Inputs!$B$86,1+INT((Y3-Inputs!$B$84)/3)))*Inputs!$B$83 -> 75000
A12: Выручка всего | B12: =B10+B11 -> 6360 | C12: =C10+C11 -> 10113.6 | D12: =D10+D11 -> 13841.208 | E12: =E10+E11 -> 18756.29 | F12: =F10+F11 -> 24065.934 | G12: =G10+G11 -> 29829.202 | H12: =H10+H11 -> 36111.541 | I12: =I10+I11 -> 42985.591 | ... Y12: =Y10+Y11 -> 414926.11
A13: Fee+tax | B13: =B12*(Inputs!$B$6+Inputs!$B$7) -> 572.4 | C13: =C12*(Inputs!$B$6+Inputs!$B$7) -> 910.224 | D13: =D12*(Inputs!$B$6+Inputs!$B$7) -> 1245.7087 | E13: =E12*(Inputs!$B$6+Inputs!$B$7) -> 1688.0661 | F13: =F12*(Inputs!$B$6+Inputs!$B$7) -> 2165.9341 | G13: =G12*(Inputs!$B$6+Inputs!$B$7) -> 2684.6282 | H13: =H12*(Inputs!$B$6+Inputs!$B$7) -> 3250.0387 | I13: =I12*(Inputs!$B$6+Inputs!$B$7) -> 3868.7032 | ... Y13: =Y12*(Inputs!$B$6+Inputs!$B$7) -> 37343.35
A14: LLM всего | B14: =B5*Inputs!$B$115+Inputs!$B$111+B5/1000*Inputs!$B$59 -> 32.565243 | C14: =C5*Inputs!$B$115+Inputs!$B$111+C5/1000*Inputs!$B$59 -> 38.235441 | D14: =D5*Inputs!$B$115+Inputs!$B$111+D5/1000*Inputs!$B$59 -> 44.284365 | E14: =E5*Inputs!$B$115+Inputs!$B$111+E5/1000*Inputs!$B$59 -> 50.775565 | F14: =F5*Inputs!$B$115+Inputs!$B$111+F5/1000*Inputs!$B$59 -> 57.779129 | G14: =G5*Inputs!$B$115+Inputs!$B$111+G5/1000*Inputs!$B$59 -> 65.372536 | H14: =H5*Inputs!$B$115+Inputs!$B$111+H5/1000*Inputs!$B$59 -> 73.641601 | I14: =I5*Inputs!$B$115+Inputs!$B$111+I5/1000*Inputs!$B$59 -> 82.681538 | ... Y14: =Y5*Inputs!$B$115+Inputs!$B$111+Y5/1000*Inputs!$B$59 -> 471.56364
A15: Инфра (серверы) | B15: =IF(B5<=0,Inputs!$B$66,IF(B5<=Inputs!$B$68,Inputs!$B$67,IF(B5<=Inputs!$B$70,Inputs!$B$69,Inputs!$B$71))) -> 3800 | C15: =IF(C5<=0,Inputs!$B$66,IF(C5<=Inputs!$B$68,Inputs!$B$67,IF(C5<=Inputs!$B$70,Inputs!$B$69,Inputs!$B$71))) -> 3800 | D15: =IF(D5<=0,Inputs!$B$66,IF(D5<=Inputs!$B$68,Inputs!$B$67,IF(D5<=Inputs!$B$70,Inputs!$B$69,Inputs!$B$71))) -> 3800 | E15: =IF(E5<=0,Inputs!$B$66,IF(E5<=Inputs!$B$68,Inputs!$B$67,IF(E5<=Inputs!$B$70,Inputs!$B$69,Inputs!$B$71))) -> 3800 | F15: =IF(F5<=0,Inputs!$B$66,IF(F5<=Inputs!$B$68,Inputs!$B$67,IF(F5<=Inputs!$B$70,Inputs!$B$69,Inputs!$B$71))) -> 14800 | G15: =IF(G5<=0,Inputs!$B$66,IF(G5<=Inputs!$B$68,Inputs!$B$67,IF(G5<=Inputs!$B$70,Inputs!$B$69,Inputs!$B$71))) -> 14800 | H15: =IF(H5<=0,Inputs!$B$66,IF(H5<=Inputs!$B$68,Inputs!$B$67,IF(H5<=Inputs!$B$70,Inputs!$B$69,Inputs!$B$71))) -> 14800 | I15: =IF(I5<=0,Inputs!$B$66,IF(I5<=Inputs!$B$68,Inputs!$B$67,IF(I5<=Inputs!$B$70,Inputs!$B$69,Inputs!$B$71))) -> 14800 | ... Y15: =IF(Y5<=0,Inputs!$B$66,IF(Y5<=Inputs!$B$68,Inputs!$B$67,IF(Y5<=Inputs!$B$70,Inputs!$B$69,Inputs!$B$71))) -> 34800
A16: Домен (год) | B16: =IF(OR(B3=1,AND(B3>1,MOD(B3-1,12)=0)),Inputs!$B$93,0) -> 1000 | C16: =IF(OR(C3=1,AND(C3>1,MOD(C3-1,12)=0)),Inputs!$B$93,0) -> 0 | D16: =IF(OR(D3=1,AND(D3>1,MOD(D3-1,12)=0)),Inputs!$B$93,0) -> 0 | E16: =IF(OR(E3=1,AND(E3>1,MOD(E3-1,12)=0)),Inputs!$B$93,0) -> 0 | F16: =IF(OR(F3=1,AND(F3>1,MOD(F3-1,12)=0)),Inputs!$B$93,0) -> 0 | G16: =IF(OR(G3=1,AND(G3>1,MOD(G3-1,12)=0)),Inputs!$B$93,0) -> 0 | H16: =IF(OR(H3=1,AND(H3>1,MOD(H3-1,12)=0)),Inputs!$B$93,0) -> 0 | I16: =IF(OR(I3=1,AND(I3>1,MOD(I3-1,12)=0)),Inputs!$B$93,0) -> 0 | ... Y16: =IF(OR(Y3=1,AND(Y3>1,MOD(Y3-1,12)=0)),Inputs!$B$93,0) -> 0
A17: Админ | B17: =IF(B12>=Inputs!$B$63,Inputs!$B$62,0)+Inputs!$B$74+Inputs!$B$75 -> 2500 | C17: =IF(C12>=Inputs!$B$63,Inputs!$B$62,0)+Inputs!$B$74+Inputs!$B$75 -> 6700 | D17: =IF(D12>=Inputs!$B$63,Inputs!$B$62,0)+Inputs!$B$74+Inputs!$B$75 -> 6700 | E17: =IF(E12>=Inputs!$B$63,Inputs!$B$62,0)+Inputs!$B$74+Inputs!$B$75 -> 6700 | F17: =IF(F12>=Inputs!$B$63,Inputs!$B$62,0)+Inputs!$B$74+Inputs!$B$75 -> 6700 | G17: =IF(G12>=Inputs!$B$63,Inputs!$B$62,0)+Inputs!$B$74+Inputs!$B$75 -> 6700 | H17: =IF(H12>=Inputs!$B$63,Inputs!$B$62,0)+Inputs!$B$74+Inputs!$B$75 -> 6700 | I17: =IF(I12>=Inputs!$B$63,Inputs!$B$62,0)+Inputs!$B$74+Inputs!$B$75 -> 6700 | ... Y17: =IF(Y12>=Inputs!$B$63,Inputs!$B$62,0)+Inputs!$B$74+Inputs!$B$75 -> 6700
A18: CAC | B18: =B36*B19*IF(B3=1,0.5,1) -> 800 | C18: =C36*C19*IF(C3=1,0.5,1) -> 2096 | D18: =D36*D19*IF(D3=1,0.5,1) -> 2633.28 | E18: =E36*E19*IF(E3=1,0.5,1) -> 3217.888 | F18: =F36*F19*IF(F3=1,0.5,1) -> 3856.5321 | G18: =G36*G19*IF(G3=1,0.5,1) -> 3417.4977 | H18: =H36*H19*IF(H3=1,0.5,1) -> 3994.9276 | I18: =I36*I19*IF(I3=1,0.5,1) -> 4631.6092 | ... Y18: =Y36*Y19*IF(Y3=1,0.5,1) -> 149057.6
A19: CAC unit | B19: =IF(B3<=12,Inputs!$B$76,Inputs!$B$77)*IF(B3>=6,1-Inputs!$B$78,1) -> 400 | C19: =IF(C3<=12,Inputs!$B$76,Inputs!$B$77)*IF(C3>=6,1-Inputs!$B$78,1) -> 400 | D19: =IF(D3<=12,Inputs!$B$76,Inputs!$B$77)*IF(D3>=6,1-Inputs!$B$78,1) -> 400 | E19: =IF(E3<=12,Inputs!$B$76,Inputs!$B$77)*IF(E3>=6,1-Inputs!$B$78,1) -> 400 | F19: =IF(F3<=12,Inputs!$B$76,Inputs!$B$77)*IF(F3>=6,1-Inputs!$B$78,1) -> 400 | G19: =IF(G3<=12,Inputs!$B$76,Inputs!$B$77)*IF(G3>=6,1-Inputs!$B$78,1) -> 300 | H19: =IF(H3<=12,Inputs!$B$76,Inputs!$B$77)*IF(H3>=6,1-Inputs!$B$78,1) -> 300 | I19: =IF(I3<=12,Inputs!$B$76,Inputs!$B$77)*IF(I3>=6,1-Inputs!$B$78,1) -> 300 | ... Y19: =IF(Y3<=12,Inputs!$B$76,Inputs!$B$77)*IF(Y3>=6,1-Inputs!$B$78,1) -> 1350
A20: GM после LLM | B20: =B12-B13-B14 -> 5755.0348 | C20: =C12-C13-C14 -> 9165.1406 | D20: =D12-D13-D14 -> 12551.215 | E20: =E12-E13-E14 -> 17017.449 | F20: =F12-F13-F14 -> 21842.221 | G20: =G12-G13-G14 -> 27079.202 | H20: =H12-H13-H14 -> 32787.861 | I20: =I12-I13-I14 -> 39034.206 | ... Y20: =Y12-Y13-Y14 -> 377111.2
A21: EBITDA pre-div | B21: =B12-B13-B14-B15-B17-B18-B16 -> -2344.9652 | C21: =C12-C13-C14-C15-C17-C18-C16 -> -3430.8594 | D21: =D12-D13-D14-D15-D17-D18-D16 -> -582.06509 | E21: =E12-E13-E14-E15-E17-E18-E16 -> 3299.5607 | F21: =F12-F13-F14-F15-F17-F18-F16 -> -3514.3109 | G21: =G12-G13-G14-G15-G17-G18-G16 -> 2161.7039 | H21: =H12-H13-H14-H15-H17-H18-H16 -> 7292.9333 | I21: =I12-I13-I14-I15-I17-I18-I16 -> 12902.597 | ... Y21: =Y12-Y13-Y14-Y15-Y17-Y18-Y16 -> 186553.6
A22: Дивиденд тебе | B22: =IF(B21>Inputs!$B$79,MAX(0,Inputs!$B$80*(B21-Inputs!$B$79)),0) -> 0 | C22: =IF(C21>Inputs!$B$79,MAX(0,Inputs!$B$80*(C21-Inputs!$B$79)),0) -> 0 | D22: =IF(D21>Inputs!$B$79,MAX(0,Inputs!$B$80*(D21-Inputs!$B$79)),0) -> 0 | E22: =IF(E21>Inputs!$B$79,MAX(0,Inputs!$B$80*(E21-Inputs!$B$79)),0) -> 0 | F22: =IF(F21>Inputs!$B$79,MAX(0,Inputs!$B$80*(F21-Inputs!$B$79)),0) -> 0 | G22: =IF(G21>Inputs!$B$79,MAX(0,Inputs!$B$80*(G21-Inputs!$B$79)),0) -> 0 | H22: =IF(H21>Inputs!$B$79,MAX(0,Inputs!$B$80*(H21-Inputs!$B$79)),0) -> 0 | I22: =IF(I21>Inputs!$B$79,MAX(0,Inputs!$B$80*(I21-Inputs!$B$79)),0) -> 0 | ... Y22: =IF(Y21>Inputs!$B$79,MAX(0,Inputs!$B$80*(Y21-Inputs!$B$79)),0) -> 68276.801
A23: EBITDA | B23: =B21-B22 -> -2344.9652 | C23: =C21-C22 -> -3430.8594 | D23: =D21-D22 -> -582.06509 | E23: =E21-E22 -> 3299.5607 | F23: =F21-F22 -> -3514.3109 | G23: =G21-G22 -> 2161.7039 | H23: =H21-H22 -> 7292.9333 | I23: =I21-I22 -> 12902.597 | ... Y23: =Y21-Y22 -> 118276.8
A24: Маржа | B24: =IF(B12=0,0,B23/B12) -> -0.36870523 | C24: =IF(C12=0,0,C23/C12) -> -0.33923227 | D24: =IF(D12=0,0,D23/D12) -> -0.042053055 | E24: =IF(E12=0,0,E23/E12) -> 0.17591755 | F24: =IF(F12=0,0,F23/F12) -> -0.14602844 | G24: =IF(G12=0,0,G23/G12) -> 0.072469385 | H24: =IF(H12=0,0,H23/H12) -> 0.20195575 | I24: =IF(I12=0,0,I23/I12) -> 0.30016097 | ... Y24: =IF(Y12=0,0,Y23/Y12) -> 0.28505509
A26: Сумма выручки 24м | B26: =SUM(B12:Y12) -> 3645060.8
A27: Сумма Lifetime 24м | B27: =SUM(B9:Y9) -> 822609.26
A28: Сумма LLM 24м | B28: =SUM(B14:Y14) -> 4225.7565
A29: Сумма инфра 24м | B29: =SUM(B15:Y15) -> 551200
A30: Сумма CAC 24м | B30: =SUM(B18:Y18) -> 1070965.9
A31: Сумма EBITDA 24м | B31: =SUM(B23:Y23) -> 1133766.7
A32: Дивиденд тебе 24м | B32: =SUM(B22:Y22) -> 398247
A33: Угроза = Personal runway + медленный набор (см. Pes), не LLM
A36: new_pay (служебное) | B36: =B7 -> 4 | C36: =MAX(0,C7-B7*(1-Inputs!$B$30)) -> 5.24 | D36: =MAX(0,D7-C7*(1-Inputs!$B$30)) -> 6.5832 | E36: =MAX(0,E7-D7*(1-Inputs!$B$30)) -> 8.04472 | F36: =MAX(0,F7-E7*(1-Inputs!$B$30)) -> 9.6413302 | G36: =MAX(0,G7-F7*(1-Inputs!$B$30)) -> 11.391659 | H36: =MAX(0,H7-G7*(1-Inputs!$B$30)) -> 13.316425 | I36: =MAX(0,I7-H7*(1-Inputs!$B$30)) -> 15.438697 | J36: =MAX(0,J7-I7*(1-Inputs!$B$30)) -> 17.784184 | ... Y36: =MAX(0,Y7-X7*(1-Inputs!$B$30)) -> 110.41303
A37: new_lt (служебное) | B37: =B36*Inputs!$B$15 -> 1.2 | C37: =C36*Inputs!$B$15 -> 1.572 | D37: =D36*Inputs!$B$15 -> 1.97496 | E37: =E36*Inputs!$B$15 -> 2.413416 | F37: =F36*Inputs!$B$15 -> 2.8923991 | G37: =G36*Inputs!$B$15 -> 3.4174977 | H37: =H36*Inputs!$B$15 -> 3.9949276 | I37: =I36*Inputs!$B$15 -> 4.6316092 | ... Y37: =Y36*Inputs!$B$15 -> 33.12391
A38: lt_active (служебное) | B38: =SUM(INDEX($B$37:$Y$37,1,MAX(1,B3-Inputs!$B$61+1)):INDEX($B$37:$Y$37,1,B3)) -> 1.2 | C38: =SUM(INDEX($B$37:$Y$37,1,MAX(1,C3-Inputs!$B$61+1)):INDEX($B$37:$Y$37,1,C3)) -> 2.772 | D38: =SUM(INDEX($B$37:$Y$37,1,MAX(1,D3-Inputs!$B$61+1)):INDEX($B$37:$Y$37,1,D3)) -> 4.74696 | E38: =SUM(INDEX($B$37:$Y$37,1,MAX(1,E3-Inputs!$B$61+1)):INDEX($B$37:$Y$37,1,E3)) -> 5.960376 | F38: =SUM(INDEX($B$37:$Y$37,1,MAX(1,F3-Inputs!$B$61+1)):INDEX($B$37:$Y$37,1,F3)) -> 7.2807751 | G38: =SUM(INDEX($B$37:$Y$37,1,MAX(1,G3-Inputs!$B$61+1)):INDEX($B$37:$Y$37,1,G3)) -> 8.7233128 | H38: =SUM(INDEX($B$37:$Y$37,1,MAX(1,H3-Inputs!$B$61+1)):INDEX($B$37:$Y$37,1,H3)) -> 10.304824 | I38: =SUM(INDEX($B$37:$Y$37,1,MAX(1,I3-Inputs!$B$61+1)):INDEX($B$37:$Y$37,1,I3)) -> 12.044034 | ... Y38: =SUM(INDEX($B$37:$Y$37,1,MAX(1,Y3-Inputs!$B$61+1)):INDEX($B$37:$Y$37,1,Y3)) -> 88.95072
A39: sub_pay (служебное) | B39: =MAX(0,B7-B38) -> 2.8 | C39: =MAX(0,C7-C38) -> 5.468 | D39: =MAX(0,D7-D38) -> 8.01624 | E39: =MAX(0,E7-E38) -> 11.656744 | F39: =MAX(0,F7-F38) -> 15.573395 | G39: =MAX(0,G7-G38) -> 19.808974 | H39: =MAX(0,H7-H38) -> 24.410816 | I39: =MAX(0,I7-I38) -> 29.431393 | ... Y39: =MAX(0,Y7-Y38) -> 243.31881

Sheet CashFlow
A1: Две кассы: Business + Personal
A3: Мес | B3: 1 | C3: 2 | D3: 3 | E3: 4 | F3: 5 | G3: 6 | H3: 7 | I3: 8 | J3: 9 | K3: 10 | L3: 11 | M3: 12 | N3: 13 | O3: 14 | P3: 15 | Q3: 16 | R3: 17 | S3: 18 | T3: 19 | U3: 20 | V3: 21 | W3: 22 | X3: 23 | Y3: 24
A4: Biz начало | B4: =Inputs!$B$92 -> 30000 | C4: =B8 -> 23655.035 | D4: =C8 -> 20224.175 | E4: =D8 -> 19642.11 | F4: =E8 -> 22941.671 | G4: =F8 -> 19427.36 | H4: =G8 -> 21589.064 | I4: =H8 -> 28881.997 | J4: =I8 -> 41784.594 | ... Y4: =X8 -> 1041489.9
A5: EBITDA | B5: =PnL!B23 -> -2344.9652 | C5: =PnL!C23 -> -3430.8594 | D5: =PnL!D23 -> -582.06509 | E5: =PnL!E23 -> 3299.5607 | F5: =PnL!F23 -> -3514.3109 | G5: =PnL!G23 -> 2161.7039 | H5: =PnL!H23 -> 7292.9333 | I5: =PnL!I23 -> 12902.597 | ... Y5: =PnL!Y23 -> 118276.8
A6: Capex | B6: =IF(B3=1,Inputs!$B$94,0) -> 4000 | C6: =IF(C3=1,Inputs!$B$94,0) -> 0 | D6: =IF(D3=1,Inputs!$B$94,0) -> 0 | E6: =IF(E3=1,Inputs!$B$94,0) -> 0 | F6: =IF(F3=1,Inputs!$B$94,0) -> 0 | G6: =IF(G3=1,Inputs!$B$94,0) -> 0 | H6: =IF(H3=1,Inputs!$B$94,0) -> 0 | I6: =IF(I3=1,Inputs!$B$94,0) -> 0 | ... Y6: =IF(Y3=1,Inputs!$B$94,0) -> 0
A7: Bailout из личного | B7: =MAX(0,-(B4+B5-B6)) -> 0 | C7: =MAX(0,-(C4+C5-C6)) -> 0 | D7: =MAX(0,-(D4+D5-D6)) -> 0 | E7: =MAX(0,-(E4+E5-E6)) -> 0 | F7: =MAX(0,-(F4+F5-F6)) -> 0 | G7: =MAX(0,-(G4+G5-G6)) -> 0 | H7: =MAX(0,-(H4+H5-H6)) -> 0 | I7: =MAX(0,-(I4+I5-I6)) -> 0 | ... Y7: =MAX(0,-(Y4+Y5-Y6)) -> 0
A8: Biz конец | B8: =MAX(0,B4+B5-B6) -> 23655.035 | C8: =MAX(0,C4+C5-C6) -> 20224.175 | D8: =MAX(0,D4+D5-D6) -> 19642.11 | E8: =MAX(0,E4+E5-E6) -> 22941.671 | F8: =MAX(0,F4+F5-F6) -> 19427.36 | G8: =MAX(0,G4+G5-G6) -> 21589.064 | H8: =MAX(0,H4+H5-H6) -> 28881.997 | I8: =MAX(0,I4+I5-I6) -> 41784.594 | ... Y8: =MAX(0,Y4+Y5-Y6) -> 1159766.7
A9: Personal начало | B9: =Inputs!$B$89 -> 300000 | C9: =B13 -> 280000 | D9: =C13 -> 260000 | E9: =D13 -> 240000 | F9: =E13 -> 220000 | G9: =F13 -> 200000 | H9: =G13 -> 180000 | I9: =H13 -> 160000 | J9: =I13 -> 140000 | ... Y9: =X13 -> 169970.2
A10: Жизнь | B10: =Inputs!$B$90 -> 60000 | C10: =Inputs!$B$90 -> 60000 | D10: =Inputs!$B$90 -> 60000 | E10: =Inputs!$B$90 -> 60000 | F10: =Inputs!$B$90 -> 60000 | G10: =Inputs!$B$90 -> 60000 | H10: =Inputs!$B$90 -> 60000 | I10: =Inputs!$B$90 -> 60000 | ... Y10: =Inputs!$B$90 -> 60000
A11: Подработка | B11: =Inputs!$B$91 -> 40000 | C11: =Inputs!$B$91 -> 40000 | D11: =Inputs!$B$91 -> 40000 | E11: =Inputs!$B$91 -> 40000 | F11: =Inputs!$B$91 -> 40000 | G11: =Inputs!$B$91 -> 40000 | H11: =Inputs!$B$91 -> 40000 | I11: =Inputs!$B$91 -> 40000 | ... Y11: =Inputs!$B$91 -> 40000
A12: Дивиденд | B12: =PnL!B22 -> 0 | C12: =PnL!C22 -> 0 | D12: =PnL!D22 -> 0 | E12: =PnL!E22 -> 0 | F12: =PnL!F22 -> 0 | G12: =PnL!G22 -> 0 | H12: =PnL!H22 -> 0 | I12: =PnL!I22 -> 0 | ... Y12: =PnL!Y22 -> 68276.801
A13: Personal конец | B13: =B9-B10+B11+B12-B7 -> 280000 | C13: =C9-C10+C11+C12-C7 -> 260000 | D13: =D9-D10+D11+D12-D7 -> 240000 | E13: =E9-E10+E11+E12-E7 -> 220000 | F13: =F9-F10+F11+F12-F7 -> 200000 | G13: =G9-G10+G11+G12-G7 -> 180000 | H13: =H9-H10+H11+H12-H7 -> 160000 | I13: =I9-I10+I11+I12-I7 -> 140000 | ... Y13: =Y9-Y10+Y11+Y12-Y7 -> 218247

Sheet Scenarios
A1: Base / Optimistic / Pessimistic — соло
B3: Base | C3: Optimistic | D3: Pessimistic
A4: ARPU sub-эквив | B4: 39.6 | C4: 71.8 | D4: 16.8
A5: Платящих % | B5: 0.04 | C5: 0.07 | D5: 0.02
A6: Time-to-100 users | B6: 1 | C6: 1 | D6: 7
A7: Мес. первого платящего | B7: 1 | C7: 1 | D7: 4
A8: Мес. 60 платящих | B8: 11 | C8: 4 | D8: 0
A9: Личные ₽ кончаются в мес. | B9: 0 | C9: 0 | D9: 14
A10: Юзеры мес12 | B10: =PnL!L5 -> 1900.0309 | C10: 3800.0619 | D10: 228.00371
A11: WAS мес12 | B11: =PnL!L6 -> 475.00773 | C11: 950.01547 | D11: 57.000928
A12: Платящие мес12 | B12: =PnL!L7 -> 76.001237 | C12: 266.00433 | D12: 4.5600742
A13: Выручка мес12 | B13: =PnL!L12 -> 78157.069 | C13: 478871.71 | D13: 4337.8525
A14: Lifetime мес12 | B14: =PnL!L9 -> 23737.946 | C14: 68567.323 | D14: 1957.4987
A15: EBITDA мес12 | B15: =PnL!L23 -> 41554.967 | C15: 210539.58 | D15: -3045.1597
A16: Personal конец мес12 | B16: =CashFlow!L13 -> 60000 | C16: 612186.24 | D16: 27248.692
A17: Юзеры мес24 | B17: =PnL!Y5 -> 8306.7382 | C17: 16613.476 | D17: 996.80859
A18: Платящие мес24 | B18: =PnL!Y7 -> 332.26953 | C18: 1162.9434 | D18: 19.936172
A19: Выручка мес24 | B19: =PnL!Y12 -> 414926.11 | C19: 1464934.7 | D19: 18795.161
A20: EBITDA мес24 | B20: =PnL!Y23 -> 118276.8 | C20: 458337.26 | D20: -17007.963
A21: Personal конец мес24 | B21: =CashFlow!Y13 -> 218247 | C21: 3457872.3 | D21: -350471.44
A22: Выручка сумм 24м | B22: =PnL!B26 -> 3645060.8 | C22: 13450984 | D22: 152133.97
A23: Lifetime сумм 24м | B23: =PnL!B27 -> 822609.26 | C23: 2365060.2 | D23: 68240.841
A24: LLM сумм 24м | B24: =PnL!B28 -> 4225.7565 | C24: 8901.7539 | D24: 1029.56
A25: Инфра сумм 24м | B25: =PnL!B29 -> 551200 | C25: 673200 | D25: 157200
A26: EBITDA сумм 24м | B26: =PnL!B31 -> 1133766.7 | C26: 4695944.7 | D26: -196471.44
A28: Base=guerrilla 100/м1. Opt=Habr×2. Pes=тихий набор (долина смерти). Lifetime + CAC Y2 вшиты.

Sheet Charts
A1: Графики соло-запуска

Sheet Unit
A1: Unit — LLM ок; угроза = набор + CAC Y2
A3: ARPU платящего (sub) | B3: =Inputs!$B$114 -> 990
A4: Lifetime | B4: =Inputs!$B$14 -> 2990
A5: LLM на платящего ₽/мес | B5: =Inputs!$B$116 -> 0.25679682
A6: Запас sub после LLM | B6: =Inputs!$B$114-Inputs!$B$116 -> 989.7432
A7: LLM Free (taste) | B7: =Inputs!$B$107 -> 0.00335475
A9: LTV (sub) | B9: =Inputs!$B$117 -> 3960
A10: CAC Y1 / Y2 | B10: =Inputs!$B$76 -> 400 | C10: =Inputs!$B$77 -> 1800
A11: LTV/CAC Y1 | B11: =Inputs!$B$118 -> 9.9
A12: LTV/CAC Y2 (без referral) | B12: =Inputs!$B$119 -> 2.2
A13: LTV/CAC Y2 с referral | B13: =IF(Inputs!$B$77*(1-Inputs!$B$78)=0,0,Inputs!$B$117/(Inputs!$B$77*(1-Inputs!$B$78))) -> 2.9333333
A15: Payback Y1 ≈ CAC / (ARPU×(1-fee-tax)) | B15: =Inputs!$B$76/(Inputs!$B$114*(1-Inputs!$B$6-Inputs!$B$7)) -> 0.44400044
A17: Сумма 24м: LLM / инфра / Lifetime | B17: =PnL!B28 -> 4225.7565 | C17: =PnL!B29 -> 551200 | D17: =PnL!B27 -> 822609.26
A19: Вывод: математика бьётся. Выживание = 100 regs/мес + Plus/LT + Personal.

Sheet Dashboard
A1: DASHBOARD — соло-бутстрап
A2: Нет инвесторов. Нет команды. Старт с 0. Открой Bootstrap для помесячки.
A4: Режим | B4: solo + guerrilla GTM | C4: Сценарий | D4: 60 payers | E4: Personal dry
A5: Цены | B5: 490 / 990(+LT 2990) / 1990 | C5: Base | D5: 11 | E5: ok
A6: Платящих (base) | B6: 4% Plus-heavy | C6: Opt | D6: 4 | E6: ok
A7: Activation model | B7: 15% | C7: Pes | D7: — | E7: 14
A8: Signups мес1 | B8: 100
A9: Time-to-100 | B9: 1
A10: North Star | B10: WAS
A11: ARPU pay / LT | B11: 990 / 2990
A12: LLM Free / на pay | B12: 0.00 / 0.26
A13: LTV/CAC Y1 / Y2 | B13: 9.9 / 2.2
A14: Lifetime 24м | B14: 822609
A15: Личный burn | B15: 20000
A16: Runway мес (грубо) | B16: 15
A17: Мес → 60 pay | B17: 11
A18: Personal dry | B18: нет
A19: Выручка мес6 | B19: 29829
A20: EBITDA мес6 | B20: 2162
A21: Платящие мес6 | B21: 28.5
A22: Выручка мес12 | B22: 78157
A23: EBITDA мес12 | B23: 41555
A24: WAS мес12 | B24: 475
A25: Personal мес12 | B25: 60000
A26: Выручка мес24 | B26: 414926
A27: EBITDA мес24 | B27: 118277
A28: Personal мес24 | B28: 218247
A33: Крути на Inputs: Signups мес1, жизнь ₽/мес, личные накопления — это твои реальные рычаги.

Sheet InfraRoadmap
A1: Инфра соло
A3: 0 юзеров: 2300 ₽ (минимальный VPS)
A4: 1–500: 3800 ₽
A5: 500–2000: 14800 ₽
A6: >2000: 34800 ₽
A8: Домен ≈ 1000 ₽/год (мес 1 и 13 в PnL), не дроби на 12 в инфру.
A9: Clipper у юзеров = proxy 0. Один ты — не строй HighLoad заранее.
A10: Минус на старте ≈ эта таблица + CAC/админ. GLM при taste+paid — копейки.
